<?xml version="1.0"?>
<!--
Copyright (C) 2017, Raffaello Bonghi <raffaello@rnext.it>
All rights reserved

Redistribution and use in source and binary forms, with or without
modification, are permitted provided that the following conditions are met:

1. Redistributions of source code must retain the above copyright 
   notice, this list of conditions and the following disclaimer.
2. Redistributions in binary form must reproduce the above copyright
   notice, this list of conditions and the following disclaimer in the
   documentation and/or other materials provided with the distribution.
3. Neither the name of the copyright holder nor the names of its 
   contributors may be used to endorse or promote products derived 
   from this software without specific prior written permission.
 
THIS SOFTWARE IS PROVIDED BY THE COPYRIGHT HOLDERS AND 
CONTRIBUTORS "AS IS" AND ANY EXPRESS OR IMPLIED WARRANTIES, INCLUDING, 
BUT NOT LIMITED TO, THE IMPLIED WARRANTIES OF MERCHANTABILITY AND FITNESS 
FOR A PARTICULAR PURPOSE ARE DISCLAIMED. IN NO EVENT SHALL THE COPYRIGHT
HOLDER OR CONTRIBUTORS BE LIABLE FOR ANY DIRECT, INDIRECT, INCIDENTAL, 
SPECIAL, EXEMPLARY, OR CONSEQUENTIAL DAMAGES (INCLUDING, BUT NOT LIMITED TO,
PROCUREMENT OF SUBSTITUTE GOODS OR SERVICES; LOSS OF USE, DATA, OR PROFITS; 
OR BUSINESS INTERRUPTION) HOWEVER CAUSED AND ON ANY THEORY OF LIABILITY, 
WHETHER IN CONTRACT, STRICT LIABILITY, OR TORT (INCLUDING NEGLIGENCE 
OR OTHERWISE) ARISING IN ANY WAY OUT OF THE USE OF THIS SOFTWARE, 
EVEN IF ADVISED OF THE POSSIBILITY OF SUCH DAMAGE.
-->
<robot xmlns:xacro="http://ros.org/wiki/xacro" name="gear">

 <xacro:macro name="gear" params="type orientation">

  <link name="gear_${type}_Link">
    <inertial>
      <origin xyz="0 0 0.008" rpy="0 0 0" />
      <mass value="0.0111" />
      <inertia ixx="0" ixy="0" ixz="0"
        iyy="0" iyz="0"
        izz="0" />
    </inertial>
    <visual>
      <origin xyz="0 0 0" rpy="0 0 0" />
      <geometry>
        <mesh filename="${path_meshes}/track/gear_link.STL" />
      </geometry>
      <material name="DarkGrey" />
    </visual>
    <collision>
      <origin xyz="0 0 0" rpy="0 0 0" />
      <geometry>
        <cylinder length="0.01" radius="0.016"/>
      </geometry>
    </collision>
  </link>
  <joint name="gear_${type}_joint" type="continuous">
    <origin
      xyz="-0.0536535102814494 ${orientation * -0.00979339452125411} 0.0186240655062149"
      rpy="${orientation * M_PI/2} 0 0" />
    <parent link="track_${type}_link" />
    <child link="gear_${type}_Link" />
    <axis xyz="0 0 ${-1 * orientation}" />
    <!-- Passive sprocket rotate automatically according to the status of the active one -->
    <mimic joint="${type}_joint" multiplier="${sprocket_teeth/gear_teeth}" offset="0"/>
  </joint>

  </xacro:macro>

</robot>
